Workbook

Sheet Stellschrauben
A1: EMBERHOLD — Balancing-Stellschrauben
A2: Alle gelb hinterlegten, blauen Zellen sind Eingaben. Alles andere rechnet sich daraus. Ändere hier — die anderen Blätter folgen.
A4: LEGENDE
A5: Blau auf Gelb | B5: Eingabe — hier darfst du schrauben
A6: Schwarz | B6: Formel — nicht überschreiben
A7: Grün | B7: Verweis auf ein anderes Blatt
A9: HOLD-ÖKONOMIE
A10: Kostenwachstum pro Stufe (r) | C10: 1.11 | D10: cost(n) = Basis × r^n. Referenz: AdVenture Capitalist 1,07; Faustregel 1,15
A11: Basiskosten Gebäude (Gold) | C11: 15 | D11: Startkosten Stufe 1
A12: Basisertrag Gebäude (Einh./Min) | C12: 1 | D12: Ertrag pro Stufe
A13: Meilenstein-Intervall (Stufen) | C13: 25 | D13: Alle N Stufen verdoppelt sich der Ertrag — erzeugt die Engagement-Bumps
A14: Meilenstein-Multiplikator | C14: 2 | D14: Faktor je Meilenstein
A15: Anzahl Gebäude | C15: 6 | D15: Parallel produzierende Gebäude
A16: Gold-Anteil am Gesamtertrag | C16: 0.6 | D16: Wie viel Ertrag zu Gold wird
A18: AUFSTIEG (PRESTIGE)
A19: Splitter-Konstante (K) | C19: 10 | D19: Splitter = K × √(Spitzenertrag / Skala)
A20: Splitter-Skala | C20: 10000 | D20: Nenner der Wurzelformel
A21: Bonus je Splitter | C21: 0.02 | D21: Ertragsbonus pro Splitter
A22: Warden-Gate (Hold-Stufe) | C22: 60 | D22: Ab dieser Hold-Stufe ist Warden 1 besiegbar. MUSS unter der Wall liegen!
A24: TERRITORIUM-SKALIERUNG
A25: Gegner-HP-Wachstum je Tier | C25: 1.35
A26: Belohnungs-Wachstum je Tier | C26: 1.38 | D26: MUSS größer sein als HP-Wachstum, sonst lohnt Hochpushen nicht
A27: Gear-Machtwachstum je Tier | C27: 1.28
A28: Runen-Machtwachstum je Tier | C28: 1.06
A29: Ember-Baum je Tier (bis T10) | C29: 0.12 | D29: Additiv, deckelt bei Tier 10
A31: RUN-PACING
A32: XP-Konstante A | C32: 340 | D32: xp_bedarf(L) = A × L^k. A ergibt sich aus 'erster Pick bei 35 s'
A33: XP-Exponent k | C33: 0.799 | D33: Aus '21 Picks in 8 Min' gelöst
A34: Basis-XP-Rate (XP/Sek) | C34: 8.6
A35: Dichte-Sättigung (max) | C35: 4.4 | D35: Grenze durch Entity-Budget
A36: Buildstärke-Sättigung (max) | C36: 8
A37: Waffenslots | C37: 6
A38: Passivslots | C38: 6
A39: Stufen je Slot | C39: 5
A41: MONETARISIERUNG (Basis-Szenario)
A42: Rewarded Impressions / DAU | C42: 6
A43: Rewarded eCPM ($) | C43: 3.02 | D43: TopOn H1'25, Casual Android — Tendenz fallend
A44: Interstitial Impressions / DAU | C44: 3.2
A45: Interstitial eCPM ($) | C45: 6.5
A46: Zahleranteil | C46: 0.028
...

Sheet Hold-Kurve
A1: Hold-Ökonomie — Kosten, Ertrag, Amortisation, Wall-Erkennung
A2: Zielkorridor Wartezeit: unter 3 Min = aktive Schleife · 3–10 Min = Idle-Pause · über 30 Min = Wall. Der Warden-Gate muss VOR der Wall liegen.
A4: Stufe | B4: Kosten | C4: Ertrag/Min | D4: Ertrag-Zuwachs | E4: Amortisation (Min) | F4: Gesamteinkommen/Min | G4: Wartezeit (Min) | H4: Bewertung
A5: 1 | B5: =Stellschrauben!$C$11*Stellschrauben!$C$10^A5 -> 16.65 | C5: =Stellschrauben!$C$12*A5*Stellschrauben!$C$14^INT(A5/Stellschrauben!$C$13) -> 1 | D5: =C5 -> 1 | E5: =IFERROR(B5/D5,"") -> 16.65 | F5: =Stellschrauben!$C$15*C5*Stellschrauben!$C$16 -> 3.6 | G5: =IFERROR(B5/F5,"") -> 4.625 | H5: =IF(G5<3,"aktive Schleife",IF(G5<10,"Idle-Pause",IF(G5<30,"zäh","WALL"))) -> Idle-Pause
A6: 2 | B6: =Stellschrauben!$C$11*Stellschrauben!$C$10^A6 -> 18.4815 | C6: =Stellschrauben!$C$12*A6*Stellschrauben!$C$14^INT(A6/Stellschrauben!$C$13) -> 2 | D6: =C6-C5 -> 1 | E6: =IFERROR(B6/D6,"") -> 18.4815 | F6: =Stellschrauben!$C$15*C6*Stellschrauben!$C$16 -> 7.2 | G6: =IFERROR(B6/F6,"") -> 2.566875 | H6: =IF(G6<3,"aktive Schleife",IF(G6<10,"Idle-Pause",IF(G6<30,"zäh","WALL"))) -> aktive Schleife
A7: 3 | B7: =Stellschrauben!$C$11*Stellschrauben!$C$10^A7 -> 20.514465 | C7: =Stellschrauben!$C$12*A7*Stellschrauben!$C$14^INT(A7/Stellschrauben!$C$13) -> 3 | D7: =C7-C6 -> 1 | E7: =IFERROR(B7/D7,"") -> 20.514465 | F7: =Stellschrauben!$C$15*C7*Stellschrauben!$C$16 -> 10.8 | G7: =IFERROR(B7/F7,"") -> 1.8994875 | H7: =IF(G7<3,"aktive Schleife",IF(G7<10,"Idle-Pause",IF(G7<30,"zäh","WALL"))) -> aktive Schleife
A8: 4 | B8: =Stellschrauben!$C$11*Stellschrauben!$C$10^A8 -> 22.771056 | C8: =Stellschrauben!$C$12*A8*Stellschrauben!$C$14^INT(A8/Stellschrauben!$C$13) -> 4 | D8: =C8-C7 -> 1 | E8: =IFERROR(B8/D8,"") -> 22.771056 | F8: =Stellschrauben!$C$15*C8*Stellschrauben!$C$16 -> 14.4 | G8: =IFERROR(B8/F8,"") -> 1.5813233 | H8: =IF(G8<3,"aktive Schleife",IF(G8<10,"Idle-Pause",IF(G8<30,"zäh","WALL"))) -> aktive Schleife
A9: 5 | B9: =Stellschrauben!$C$11*Stellschrauben!$C$10^A9 -> 25.275872 | C9: =Stellschrauben!$C$12*A9*Stellschrauben!$C$14^INT(A9/Stellschrauben!$C$13) -> 5 | D9: =C9-C8 -> 1 | E9: =IFERROR(B9/D9,"") -> 25.275872 | F9: =Stellschrauben!$C$15*C9*Stellschrauben!$C$16 -> 18 | G9: =IFERROR(B9/F9,"") -> 1.4042151 | H9: =IF(G9<3,"aktive Schleife",IF(G9<10,"Idle-Pause",IF(G9<30,"zäh","WALL"))) -> aktive Schleife
A10: 6 | B10: =Stellschrauben!$C$11*Stellschrauben!$C$10^A10 -> 28.056218 | C10: =Stellschrauben!$C$12*A10*Stellschrauben!$C$14^INT(A10/Stellschrauben!$C$13) -> 6 | D10: =C10-C9 -> 1 | E10: =IFERROR(B10/D10,"") -> 28.056218 | F10: =Stellschrauben!$C$15*C10*Stellschrauben!$C$16 -> 21.6 | G10: =IFERROR(B10/F10,"") -> 1.298899 | H10: =IF(G10<3,"aktive Schleife",IF(G10<10,"Idle-Pause",IF(G10<30,"zäh","WALL"))) -> aktive Schleife
A11: 7 | B11: =Stellschrauben!$C$11*Stellschrauben!$C$10^A11 -> 31.142402 | C11: =Stellschrauben!$C$12*A11*Stellschrauben!$C$14^INT(A11/Stellschrauben!$C$13) -> 7 | D11: =C11-C10 -> 1 | E11: =IFERROR(B11/D11,"") -> 31.142402 | F11: =Stellschrauben!$C$15*C11*Stellschrauben!$C$16 -> 25.2 | G11: =IFERROR(B11/F11,"") -> 1.2358096 | H11: =IF(G11<3,"aktive Schleife",IF(G11<10,"Idle-Pause",IF(G11<30,"zäh","WALL"))) -> aktive Schleife
A12: 8 | B12: =Stellschrauben!$C$11*Stellschrauben!$C$10^A12 -> 34.568067 | C12: =Stellschrauben!$C$12*A12*Stellschrauben!$C$14^INT(A12/Stellschrauben!$C$13) -> 8 | D12: =C12-C11 -> 1 | E12: =IFERROR(B12/D12,"") -> 34.568067 | F12: =Stellschrauben!$C$15*C12*Stellschrauben!$C$16 -> 28.8 | G12: =IFERROR(B12/F12,"") -> 1.2002801 | H12: =IF(G12<3,"aktive Schleife",IF(G12<10,"Idle-Pause",IF(G12<30,"zäh","WALL"))) -> aktive Schleife
A13: 9 | B13: =Stellschrauben!$C$11*Stellschrauben!$C$10^A13 -> 38.370554 | C13: =Stellschrauben!$C$12*A13*Stellschrauben!$C$14^INT(A13/Stellschrauben!$C$13) -> 9 | D13: =C13-C12 -> 1 | E13: =IFERROR(B13/D13,"") -> 38.370554 | F13: =Stellschrauben!$C$15*C13*Stellschrauben!$C$16 -> 32.4 | G13: =IFERROR(B13/F13,"") -> 1.1842764 | H13: =IF(G13<3,"aktive Schleife",IF(G13<10,"Idle-Pause",IF(G13<30,"zäh","WALL"))) -> aktive Schleife
A14: 10 | B14: =Stellschrauben!$C$11*Stellschrauben!$C$10^A14 -> 42.591315 | C14: =Stellschrauben!$C$12*A14*Stellschrauben!$C$14^INT(A14/Stellschrauben!$C$13) -> 10 | D14: =C14-C13 -> 1 | E14: =IFERROR(B14/D14,"") -> 42.591315 | F14: =Stellschrauben!$C$15*C14*Stellschrauben!$C$16 -> 36 | G14: =IFERROR(B14/F14,"") -> 1.1830921 | H14: =IF(G14<3,"aktive Schleife",IF(G14<10,"Idle-Pause",IF(G14<30,"zäh","WALL"))) -> aktive Schleife
A15: 11 | B15: =Stellschrauben!$C$11*Stellschrauben!$C$10^A15 -> 47.276359 | C15: =Stellschrauben!$C$12*A15*Stellschrauben!$C$14^INT(A15/Stellschrauben!$C$13) -> 11 | D15: =C15-C14 -> 1 | E15: =IFERROR(B15/D15,"") -> 47.276359 | F15: =Stellschrauben!$C$15*C15*Stellschrauben!$C$16 -> 39.6 | G15: =IFERROR(B15/F15,"") -> 1.1938475 | H15: =IF(G15<3,"aktive Schleife",IF(G15<10,"Idle-Pause",IF(G15<30,"zäh","WALL"))) -> aktive Schleife
A16: 12 | B16: =Stellschrauben!$C$11*Stellschrauben!$C$10^A16 -> 52.476759 | C16: =Stellschrauben!$C$12*A16*Stellschrauben!$C$14^INT(A16/Stellschrauben!$C$13) -> 12 | D16: =C16-C15 -> 1 | E16: =IFERROR(B16/D16,"") -> 52.476759 | F16: =Stellschrauben!$C$15*C16*Stellschrauben!$C$16 -> 43.2 | G16: =IFERROR(B16/F16,"") -> 1.2147398 | H16: =IF(G16<3,"aktive Schleife",IF(G16<10,"Idle-Pause",IF(G16<30,"zäh","WALL"))) -> aktive Schleife
A17: 13 | B17: =Stellschrauben!$C$11*Stellschrauben!$C$10^A17 -> 58.249202 | C17: =Stellschrauben!$C$12*A17*Stellschrauben!$C$14^INT(A17/Stellschrauben!$C$13) -> 13 | D17: =C17-C16 -> 1 | E17: =IFERROR(B17/D17,"") -> 58.249202 | F17: =Stellschrauben!$C$15*C17*Stellschrauben!$C$16 -> 46.8 | G17: =IFERROR(B17/F17,"") -> 1.2446411 | H17: =IF(G17<3,"aktive Schleife",IF(G17<10,"Idle-Pause",IF(G17<30,"zäh","WALL"))) -> aktive Schleife
... A124: 120 | B124: =Stellschrauben!$C$11*Stellschrauben!$C$10^A124 -> 4119539.9 | C124: =Stellschrauben!$C$12*A124*Stellschrauben!$C$14^INT(A124/Stellschrauben!$C$13) -> 1920 | D124: =C124-C123 -> 16 | E124: =IFERROR(B124/D124,"") -> 257471.24 | F124: =Stellschrauben!$C$15*C124*Stellschrauben!$C$16 -> 6912 | G124: =IFERROR(B124/F124,"") -> 595.99825 | H124: =IF(G124<3,"aktive Schleife",IF(G124<10,"Idle-Pause",IF(G124<30,"zäh","WALL"))) -> WALL

Sheet Aufstieg
A1: Aufstiegs-Zyklen — Splitter, Bonus, Zyklusdauer
A2: Ziel: Zyklusdauer bleibt im Korridor 6–12 h. Zyklen sollen nicht länger werden, nur wertvoller.
A4: Basisertrag Hold (Ember/h) | B4: 400
A5: Hold-Ausbaufaktor | B5: 25
A6: Territorien-Faktor je Zyklus | B6: 1.5
A7: Territorien-Deckel (Zyklen) | B7: 8
A9: Zyklus | B9: Splitter gesamt (Vorzyklus) | C9: Splitter-Bonus | D9: Territorien-Faktor | E9: Spitzenertrag Ember/h | F9: Splitter dazu | G9: Splitter gesamt | H9: Dauer (h) | I9: kumuliert (h)
A10: 1 | B10: =0 -> 0 | C10: =1+Stellschrauben!$C$21*B10 -> 1 | D10: =$B$6^MIN(A10-1,$B$7) -> 1 | E10: =$B$4*C10*D10*$B$5 -> 10000 | F10: =Stellschrauben!$C$19*SQRT(E10/Stellschrauben!$C$20) -> 10 | G10: =B10+F10 -> 10 | H10: =MAX(2,6+1.6*LOG(E10/($B$4*$B$5),2)/MAX(C10^0.35,1)) -> 6 | I10: =H10 -> 6
A11: 2 | B11: =G10 -> 10 | C11: =1+Stellschrauben!$C$21*B11 -> 1.2 | D11: =$B$6^MIN(A11-1,$B$7) -> 1.5 | E11: =$B$4*C11*D11*$B$5 -> 18000 | F11: =Stellschrauben!$C$19*SQRT(E11/Stellschrauben!$C$20) -> 13.416408 | G11: =B11+F11 -> 23.416408 | H11: =MAX(2,6+1.6*LOG(E11/($B$4*$B$5),2)/MAX(C11^0.35,1)) -> 7.2729191 | I11: =I10+H11 -> 13.272919
A12: 3 | B12: =G11 -> 23.416408 | C12: =1+Stellschrauben!$C$21*B12 -> 1.4683282 | D12: =$B$6^MIN(A12-1,$B$7) -> 2.25 | E12: =$B$4*C12*D12*$B$5 -> 33037.384 | F12: =Stellschrauben!$C$19*SQRT(E12/Stellschrauben!$C$20) -> 18.176189 | G12: =B12+F12 -> 41.592597 | H12: =MAX(2,6+1.6*LOG(E12/($B$4*$B$5),2)/MAX(C12^0.35,1)) -> 8.4115385 | I12: =I11+H12 -> 21.684458
A13: 4 | B13: =G12 -> 41.592597 | C13: =1+Stellschrauben!$C$21*B13 -> 1.8318519 | D13: =$B$6^MIN(A13-1,$B$7) -> 3.375 | E13: =$B$4*C13*D13*$B$5 -> 61825.003 | F13: =Stellschrauben!$C$19*SQRT(E13/Stellschrauben!$C$20) -> 24.864634 | G13: =B13+F13 -> 66.457231 | H13: =MAX(2,6+1.6*LOG(E13/($B$4*$B$5),2)/MAX(C13^0.35,1)) -> 9.4022418 | I13: =I12+H13 -> 31.086699
A14: 5 | B14: =G13 -> 66.457231 | C14: =1+Stellschrauben!$C$21*B14 -> 2.3291446 | D14: =$B$6^MIN(A14-1,$B$7) -> 5.0625 | E14: =$B$4*C14*D14*$B$5 -> 117912.95 | F14: =Stellschrauben!$C$19*SQRT(E14/Stellschrauben!$C$20) -> 34.338455 | G14: =B14+F14 -> 100.79569 | H14: =MAX(2,6+1.6*LOG(E14/($B$4*$B$5),2)/MAX(C14^0.35,1)) -> 10.236513 | I14: =I13+H14 -> 41.323212
A15: 6 | B15: =G14 -> 100.79569 | C15: =1+Stellschrauben!$C$21*B15 -> 3.0159137 | D15: =$B$6^MIN(A15-1,$B$7) -> 7.59375 | E15: =$B$4*C15*D15*$B$5 -> 229020.95 | F15: =Stellschrauben!$C$19*SQRT(E15/Stellschrauben!$C$20) -> 47.856133 | G15: =B15+F15 -> 148.65182 | H15: =MAX(2,6+1.6*LOG(E15/($B$4*$B$5),2)/MAX(C15^0.35,1)) -> 10.911483 | I15: =I14+H15 -> 52.234696
A16: 7 | B16: =G15 -> 148.65182 | C16: =1+Stellschrauben!$C$21*B16 -> 3.9730364 | D16: =$B$6^MIN(A16-1,$B$7) -> 11.390625 | E16: =$B$4*C16*D16*$B$5 -> 452553.67 | F16: =Stellschrauben!$C$19*SQRT(E16/Stellschrauben!$C$20) -> 67.27211 | G16: =B16+F16 -> 215.92393 | H16: =MAX(2,6+1.6*LOG(E16/($B$4*$B$5),2)/MAX(C16^0.35,1)) -> 11.429891 | I16: =I15+H16 -> 63.664587
A17: 8 | B17: =G16 -> 215.92393 | C17: =1+Stellschrauben!$C$21*B17 -> 5.3184786 | D17: =$B$6^MIN(A17-1,$B$7) -> 17.085938 | E17: =$B$4*C17*D17*$B$5 -> 908711.92 | F17: =Stellschrauben!$C$19*SQRT(E17/Stellschrauben!$C$20) -> 95.326383 | G17: =B17+F17 -> 311.25031 | H17: =MAX(2,6+1.6*LOG(E17/($B$4*$B$5),2)/MAX(C17^0.35,1)) -> 11.799517 | I17: =I16+H17 -> 75.464104
A18: 9 | B18: =G17 -> 311.25031 | C18: =1+Stellschrauben!$C$21*B18 -> 7.2250062 | D18: =$B$6^MIN(A18-1,$B$7) -> 25.628906 | E18: =$B$4*C18*D18*$B$5 -> 1851690.1 | F18: =Stellschrauben!$C$19*SQRT(E18/Stellschrauben!$C$20) -> 136.07682 | G18: =B18+F18 -> 447.32713 | H18: =MAX(2,6+1.6*LOG(E18/($B$4*$B$5),2)/MAX(C18^0.35,1)) -> 12.03222 | I18: =I17+H18 -> 87.496324
A19: 10 | B19: =G18 -> 447.32713 | C19: =1+Stellschrauben!$C$21*B19 -> 9.9465426 | D19: =$B$6^MIN(A19-1,$B$7) -> 25.628906 | E19: =$B$4*C19*D19*$B$5 -> 2549190.1 | F19: =Stellschrauben!$C$19*SQRT(E19/Stellschrauben!$C$20) -> 159.66183 | G19: =B19+F19 -> 606.98896 | H19: =MAX(2,6+1.6*LOG(E19/($B$4*$B$5),2)/MAX(C19^0.35,1)) -> 11.723915 | I19: =I18+H19 -> 99.220239
A20: 11 | B20: =G19 -> 606.98896 | C20: =1+Stellschrauben!$C$21*B20 -> 13.139779 | D20: =$B$6^MIN(A20-1,$B$7) -> 25.628906 | E20: =$B$4*C20*D20*$B$5 -> 3367581.7 | F20: =Stellschrauben!$C$19*SQRT(E20/Stellschrauben!$C$20) -> 183.50972 | G20: =B20+F20 -> 790.49868 | H20: =MAX(2,6+1.6*LOG(E20/($B$4*$B$5),2)/MAX(C20^0.35,1)) -> 11.453362 | I20: =I19+H20 -> 110.6736
A21: 12 | B21: =G20 -> 790.49868 | C21: =1+Stellschrauben!$C$21*B21 -> 16.809974 | D21: =$B$6^MIN(A21-1,$B$7) -> 25.628906 | E21: =$B$4*C21*D21*$B$5 -> 4308212.4 | F21: =Stellschrauben!$C$19*SQRT(E21/Stellschrauben!$C$20) -> 207.56234 | G21: =B21+F21 -> 998.06102 | H21: =MAX(2,6+1.6*LOG(E21/($B$4*$B$5),2)/MAX(C21^0.35,1)) -> 11.214666 | I21: =I20+H21 -> 121.88827
A22: 13 | B22: =G21 -> 998.06102 | C22: =1+Stellschrauben!$C$21*B22 -> 20.96122 | D22: =$B$6^MIN(A22-1,$B$7) -> 25.628906 | E22: =$B$4*C22*D22*$B$5 -> 5372131.5 | F22: =Stellschrauben!$C$19*SQRT(E22/Stellschrauben!$C$20) -> 231.77859 | G22: =B22+F22 -> 1229.8396 | H22: =MAX(2,6+1.6*LOG(E22/($B$4*$B$5),2)/MAX(C22^0.35,1)) -> 11.002653 | I22: =I21+H22 -> 132.89092
... A29: 20 | B29: =G28 -> 3135.2074 | C29: =1+Stellschrauben!$C$21*B29 -> 63.704149 | D29: =$B$6^MIN(A29-1,$B$7) -> 25.628906 | E29: =$B$4*C29*D29*$B$5 -> 16326677 | F29: =Stellschrauben!$C$19*SQRT(E29/Stellschrauben!$C$20) -> 404.06282 | G29: =B29+F29 -> 3539.2703 | H29: =MAX(2,6+1.6*LOG(E29/($B$4*$B$5),2)/MAX(C29^0.35,1)) -> 9.9897751 | I29: =I28+H29 -> 205.48785
A31: PRÜFUNG | B31: Alle Zyklen im 6–12-h-Korridor? | D31: =IF(AND(MIN(H10:H29)>=5,MAX(H10:H29)<=14),"OK","AUSSERHALB") -> OK
B32: Verdopplungs-Verhältnis (soll ≈ 4×) | D32: =E14/E12 -> 3.5690764

Sheet Territorien
A1: Territorium-Tiers — Schwierigkeit, Macht, Belohnung
A2: Machtquote muss über 1,0 liegen und langsam steigen. Belohnungswachstum muss über HP-Wachstum liegen.
A4: Tier | B4: Gegner-HP | C4: Gear-Macht | D4: Runen-Macht | E4: Ember-Baum | F4: Spielermacht gesamt | G4: Machtquote | H4: Belohnung | I4: Lohnt Hochpushen?
A5: 0 | B5: =Stellschrauben!$C$25^A5 -> 1 | C5: =Stellschrauben!$C$27^A5 -> 1 | D5: =Stellschrauben!$C$28^A5 -> 1 | E5: =1+Stellschrauben!$C$29*MIN(A5,10) -> 1 | F5: =C5*D5*E5 -> 1 | G5: =F5/B5 -> 1 | H5: =Stellschrauben!$C$26^A5 -> 1 | I5: =IF(H5>=B5,"ja","NEIN — Kurve prüfen") -> ja
A6: 1 | B6: =Stellschrauben!$C$25^A6 -> 1.35 | C6: =Stellschrauben!$C$27^A6 -> 1.28 | D6: =Stellschrauben!$C$28^A6 -> 1.06 | E6: =1+Stellschrauben!$C$29*MIN(A6,10) -> 1.12 | F6: =C6*D6*E6 -> 1.519616 | G6: =F6/B6 -> 1.1256415 | H6: =Stellschrauben!$C$26^A6 -> 1.38 | I6: =IF(H6>=B6,"ja","NEIN — Kurve prüfen") -> ja
A7: 2 | B7: =Stellschrauben!$C$25^A7 -> 1.8225 | C7: =Stellschrauben!$C$27^A7 -> 1.6384 | D7: =Stellschrauben!$C$28^A7 -> 1.1236 | E7: =1+Stellschrauben!$C$29*MIN(A7,10) -> 1.24 | F7: =C7*D7*E7 -> 2.2827237 | G7: =F7/B7 -> 1.2525233 | H7: =Stellschrauben!$C$26^A7 -> 1.9044 | I7: =IF(H7>=B7,"ja","NEIN — Kurve prüfen") -> ja
A8: 3 | B8: =Stellschrauben!$C$25^A8 -> 2.460375 | C8: =Stellschrauben!$C$27^A8 -> 2.097152 | D8: =Stellschrauben!$C$28^A8 -> 1.191016 | E8: =1+Stellschrauben!$C$29*MIN(A8,10) -> 1.36 | F8: =C8*D8*E8 -> 3.3969286 | G8: =F8/B8 -> 1.3806548 | H8: =Stellschrauben!$C$26^A8 -> 2.628072 | I8: =IF(H8>=B8,"ja","NEIN — Kurve prüfen") -> ja
A9: 4 | B9: =Stellschrauben!$C$25^A9 -> 3.3215063 | C9: =Stellschrauben!$C$27^A9 -> 2.6843546 | D9: =Stellschrauben!$C$28^A9 -> 1.262477 | E9: =1+Stellschrauben!$C$29*MIN(A9,10) -> 1.48 | F9: =C9*D9*E9 -> 5.015625 | G9: =F9/B9 -> 1.5100453 | H9: =Stellschrauben!$C$26^A9 -> 3.6267394 | I9: =IF(H9>=B9,"ja","NEIN — Kurve prüfen") -> ja
A10: 5 | B10: =Stellschrauben!$C$25^A10 -> 4.4840334 | C10: =Stellschrauben!$C$27^A10 -> 3.4359738 | D10: =Stellschrauben!$C$28^A10 -> 1.3382256 | E10: =1+Stellschrauben!$C$29*MIN(A10,10) -> 1.6 | F10: =C10*D10*E10 -> 7.3569729 | G10: =F10/B10 -> 1.6407043 | H10: =Stellschrauben!$C$26^A10 -> 5.0049003 | I10: =IF(H10>=B10,"ja","NEIN — Kurve prüfen") -> ja
A11: 6 | B11: =Stellschrauben!$C$25^A11 -> 6.0534451 | C11: =Stellschrauben!$C$27^A11 -> 4.3980465 | D11: =Stellschrauben!$C$28^A11 -> 1.4185191 | E11: =1+Stellschrauben!$C$29*MIN(A11,10) -> 1.72 | F11: =C11*D11*E11 -> 10.730586 | G11: =F11/B11 -> 1.7726412 | H11: =Stellschrauben!$C$26^A11 -> 6.9067624 | I11: =IF(H11>=B11,"ja","NEIN — Kurve prüfen") -> ja
A12: 7 | B12: =Stellschrauben!$C$25^A12 -> 8.1721509 | C12: =Stellschrauben!$C$27^A12 -> 5.6294995 | D12: =Stellschrauben!$C$28^A12 -> 1.5036303 | E12: =1+Stellschrauben!$C$29*MIN(A12,10) -> 1.84 | F12: =C12*D12*E12 -> 15.575022 | G12: =F12/B12 -> 1.9058657 | H12: =Stellschrauben!$C$26^A12 -> 9.5313322 | I12: =IF(H12>=B12,"ja","NEIN — Kurve prüfen") -> ja
A13: 8 | B13: =Stellschrauben!$C$25^A13 -> 11.032404 | C13: =Stellschrauben!$C$27^A13 -> 7.2057594 | D13: =Stellschrauben!$C$28^A13 -> 1.5938481 | E13: =1+Stellschrauben!$C$29*MIN(A13,10) -> 1.96 | F13: =C13*D13*E13 -> 22.510376 | G13: =F13/B13 -> 2.0403873 | H13: =Stellschrauben!$C$26^A13 -> 13.153238 | I13: =IF(H13>=B13,"ja","NEIN — Kurve prüfen") -> ja
A14: 9 | B14: =Stellschrauben!$C$25^A14 -> 14.893745 | C14: =Stellschrauben!$C$27^A14 -> 9.223372 | D14: =Stellschrauben!$C$28^A14 -> 1.689479 | E14: =1+Stellschrauben!$C$29*MIN(A14,10) -> 2.08 | F14: =C14*D14*E14 -> 32.412001 | G14: =F14/B14 -> 2.1762157 | H14: =Stellschrauben!$C$26^A14 -> 18.151469 | I14: =IF(H14>=B14,"ja","NEIN — Kurve prüfen") -> ja
A15: 10 | B15: =Stellschrauben!$C$25^A15 -> 20.106556 | C15: =Stellschrauben!$C$27^A15 -> 11.805916 | D15: =Stellschrauben!$C$28^A15 -> 1.7908477 | E15: =1+Stellschrauben!$C$29*MIN(A15,10) -> 2.2 | F15: =C15*D15*E15 -> 46.513715 | G15: =F15/B15 -> 2.3133607 | H15: =Stellschrauben!$C$26^A15 -> 25.049027 | I15: =IF(H15>=B15,"ja","NEIN — Kurve prüfen") -> ja

Sheet Run-Pacing
A1: Run-Pacing — Kartenzüge je Modus
A2: Erster Pick bei 35 s. Rhythmus absichtlich ungleichmäßig: dünn früh, dicht spät. Kumulierte XP-Kosten begrenzen die Picks.
A4: Level | B4: XP-Bedarf für dieses Level | C4: Kumulierte XP | D4: Modus erreicht bei… | E4: Modus | F4: Dauer (Min) | G4: Kartenzüge | H4: Build-Fertigstellung
A5: 1 | B5: =Stellschrauben!$C$32*A5^Stellschrauben!$C$33 -> 340 | C5: =B5 -> 340 | E5: Scharmützel | F5: 3 | G5: 5 | H5: =G5/(Stellschrauben!$C$37+Stellschrauben!$C$38)/Stellschrauben!$C$39 -> 0.083333333
A6: 2 | B6: =Stellschrauben!$C$32*A6^Stellschrauben!$C$33 -> 591.5642 | C6: =C5+B6 -> 931.5642 | E6: Sortie | F6: 8 | G6: 21 | H6: =G6/(Stellschrauben!$C$37+Stellschrauben!$C$38)/Stellschrauben!$C$39 -> 0.35
A7: 3 | B7: =Stellschrauben!$C$32*A7^Stellschrauben!$C$33 -> 817.89735 | C7: =C6+B7 -> 1749.4615 | E7: Tiefenzug | F7: 15 | G7: 39 | H7: =G7/(Stellschrauben!$C$37+Stellschrauben!$C$38)/Stellschrauben!$C$39 -> 0.65
A8: 4 | B8: =Stellschrauben!$C$32*A8^Stellschrauben!$C$33 -> 1029.2594 | C8: =C7+B8 -> 2778.721 | E8: Wardenjagd | F8: 20 | G8: 50 | H8: =G8/(Stellschrauben!$C$37+Stellschrauben!$C$38)/Stellschrauben!$C$39 -> 0.83333333
A9: 5 | B9: =Stellschrauben!$C$32*A9^Stellschrauben!$C$33 -> 1230.144 | C9: =C8+B9 -> 4008.865
A10: 6 | B10: =Stellschrauben!$C$32*A10^Stellschrauben!$C$33 -> 1423.0553 | C10: =C9+B10 -> 5431.9202
A11: 7 | B11: =Stellschrauben!$C$32*A11^Stellschrauben!$C$33 -> 1609.5788 | C11: =C10+B11 -> 7041.4991 | E11: Prüfung: kein Modus erreicht 100 % | H11: =IF(MAX(H5:H8)<1,"OK — immer Luft nach oben","ZU VIEL") -> OK — immer Luft nach oben
A12: 8 | B12: =Stellschrauben!$C$32*A12^Stellschrauben!$C$33 -> 1790.803 | C12: =C11+B12 -> 8832.3021
A13: 9 | B13: =Stellschrauben!$C$32*A13^Stellschrauben!$C$33 -> 1967.5179 | C13: =C12+B13 -> 10799.82
A14: 10 | B14: =Stellschrauben!$C$32*A14^Stellschrauben!$C$33 -> 2140.321 | C14: =C13+B14 -> 12940.141
A15: 11 | B15: =Stellschrauben!$C$32*A15^Stellschrauben!$C$33 -> 2309.6792 | C15: =C14+B15 -> 15249.82
A16: 12 | B16: =Stellschrauben!$C$32*A16^Stellschrauben!$C$33 -> 2475.9663 | C16: =C15+B16 -> 17725.787
A17: 13 | B17: =Stellschrauben!$C$32*A17^Stellschrauben!$C$33 -> 2639.4878 | C17: =C16+B17 -> 20365.274
A18: 14 | B18: =Stellschrauben!$C$32*A18^Stellschrauben!$C$33 -> 2800.4977 | C18: =C17+B18 -> 23165.772
A19: 15 | B19: =Stellschrauben!$C$32*A19^Stellschrauben!$C$33 -> 2959.2103 | C19: =C18+B19 -> 26124.982
A20: 16 | B20: =Stellschrauben!$C$32*A20^Stellschrauben!$C$33 -> 3115.8087 | C20: =C19+B20 -> 29240.791
A21: 17 | B21: =Stellschrauben!$C$32*A21^Stellschrauben!$C$33 -> 3270.4507 | C21: =C20+B21 -> 32511.242
A22: 18 | B22: =Stellschrauben!$C$32*A22^Stellschrauben!$C$33 -> 3423.2739 | C22: =C21+B22 -> 35934.516
A23: 19 | B23: =Stellschrauben!$C$32*A23^Stellschrauben!$C$33 -> 3574.3991 | C23: =C22+B23 -> 39508.915
... A64: 60 | B64: =Stellschrauben!$C$32*A64^Stellschrauben!$C$33 -> 8958.2209 | C64: =C63+B64 -> 303220.85

Sheet Monetarisierung
A1: Umsatzmodell — ARPDAU, LTV, tragbarer CPI
A2: Alle Eingaben stehen im Blatt 'Stellschrauben'. Benchmark Hybrid-Casual ARPDAU: 0,15–0,50 $.
A4: Rewarded-Umsatz / DAU | B4: =Stellschrauben!$C$42*Stellschrauben!$C$43/1000 -> 0.01812
A5: Interstitial-Umsatz / DAU | B5: =Stellschrauben!$C$44*Stellschrauben!$C$45/1000 -> 0.0208
A6: IAP / DAU | B6: =Stellschrauben!$C$46*Stellschrauben!$C$47/30 -> 0.013066667
A7: Emberpass / DAU | B7: =Stellschrauben!$C$48*Stellschrauben!$C$49/Stellschrauben!$C$50 -> 0.011583929
A8: Abo / DAU | B8: =Stellschrauben!$C$51*Stellschrauben!$C$52/30 -> 0.001995
A9: ARPDAU gesamt | B9: =SUM(B4:B8) -> 0.065565595 | D9: Benchmark Hybrid-Casual: 0,15–0,50 $
A10: Werbe-Anteil | B10: =(B4+B5)/$B$9 -> 0.59360401 | D10: Hybrid-Casual-Muster: ~56 % Werbung / 40 % IAP / 7 % Abo
A13: RETENTION-KURVE & LTV
A14: Tag | B14: Retention | C14: kum. Spieltage | D14: kum. LTV ($)
A15: 1 | B15: =Stellschrauben!$C$53 -> 0.38
A16: 3 | B16: =Stellschrauben!$C$53*(Stellschrauben!$C$54/Stellschrauben!$C$53)^((A16-1)/6) -> 0.29621922
A17: 7 | B17: =Stellschrauben!$C$53*(Stellschrauben!$C$54/Stellschrauben!$C$53)^((A17-1)/6) -> 0.18
A18: 14 | B18: =Stellschrauben!$C$54*(Stellschrauben!$C$55/Stellschrauben!$C$54)^((A18-7)/23) -> 0.14063277
A19: 30 | B19: =Stellschrauben!$C$54*(Stellschrauben!$C$55/Stellschrauben!$C$54)^((A19-7)/23) -> 0.08
A20: 60 | B20: =Stellschrauben!$C$55*0.985^(A20-30) -> 0.050836647
A21: 90 | B21: =Stellschrauben!$C$55*0.985^(A21-30) -> 0.032304559
A22: 180 | B22: =Stellschrauben!$C$55*0.985^(A22-30) -> 0.008289428
A23: Kum. Spieltage je Installer (180 T, Näherung) | B23: 9.4 | D23: Aus balance_sim3.py per Tag-für-Tag-Integration; hier als Eingabe.
A24: LTV nach 180 Tagen | B24: =B23*$B$9 -> 0.6163166
A25: Tragbarer CPI bei ROAS 1,0 | B25: =$B$24 -> 0.6163166 | D25: Tier-1-CPI liegt bei 1,50–3,00 $ — siehe Bewertung unten.
A26: Bezahlte UA in Tier 1 tragfähig? | B26: =IF($B$24>1.5,"ja","NEIN — Web/organisch/Steam nutzen") -> NEIN — Web/organisch/Steam nutzen
A29: UMSATZ NACH DAU-STUFE
A30: DAU | B30: Umsatz / Monat | C30: Umsatz / Jahr
A31: 5000 | B31: =A31*$B$9*30 -> 9834.8393 | C31: =A31*$B$9*365 -> 119657.21
A32: 25000 | B32: =A32*$B$9*30 -> 49174.196 | C32: =A32*$B$9*365 -> 598286.06
A33: 100000 | B33: =A33*$B$9*30 -> 196696.79 | C33: =A33*$B$9*365 -> 2393144.2
A34: 400000 | B34: =A34*$B$9*30 -> 786787.14 | C34: =A34*$B$9*365 -> 9572576.9
A35: 1000000 | B35: =A35*$B$9*30 -> 1966967.9 | C35: =A35*$B$9*365 -> 23931442
A38: STEAM-PREMIUM (vierte Säule)
A39: Preis ($) | B39: 6.99
A40: Steam-Anteil | B40: 0.3
A41: MwSt-Anteil | B41: 0.19
A42: Netto je Verkauf | B42: =$B$39*(1-$B$41)*(1-$B$40) -> 3.96333
A44: Verkäufe | B44: Netto-Umsatz | C44: entspricht F2P-Monaten @25k DAU
A45: 5000 | B45: =A45*$B$42 -> 19816.65 | C45: =B45/($B$9*25000*30) -> 0.40298879
A46: 25000 | B46: =A46*$B$42 -> 99083.25 | C46: =B46/($B$9*25000*30) -> 2.014944
A47: 100000 | B47: =A47*$B$42 -> 396333 | C47: =B47/($B$9*25000*30) -> 8.0597758
A48: 500000 | B48: =A48*$B$42 -> 1981665 | C48: =B48/($B$9*25000*30) -> 40.298879

Sheet Multi-Clock
A1: Hold-Gebäude — Füllzeiten & Abdeckung je Rückkehr-Taktung
A2: Jede Rückkehr-Taktung soll mindestens ein volles Gebäude vorfinden. 'voll' = 100 %, sonst der Füllstand.
A4: Gebäude | B4: Volk | C4: Produziert | D4: Füllzeit (h) | E4: 0.5 h | F4: 2 h | G4: 8 h | H4: 12 h | I4: 24 h | J4: 72 h
A5: Tiefmine | B5: Zwerge | C5: Eisenerz, Silbererz | D5: 0.4167 | E5: =MIN(0.5/$D5,1) -> 1 | F5: =MIN(2/$D5,1) -> 1 | G5: =MIN(8/$D5,1) -> 1 | H5: =MIN(12/$D5,1) -> 1 | I5: =MIN(24/$D5,1) -> 1 | J5: =MIN(72/$D5,1) -> 1
A6: Holzfälle | B6: Sylvani | C6: Eibenholz, Sehne | D6: 0.6667 | E6: =MIN(0.5/$D6,1) -> 0.7499625 | F6: =MIN(2/$D6,1) -> 1 | G6: =MIN(8/$D6,1) -> 1 | H6: =MIN(12/$D6,1) -> 1 | I6: =MIN(24/$D6,1) -> 1 | J6: =MIN(72/$D6,1) -> 1
A7: Emberschmiede | B7: Menschen | C7: Barren | D7: 2 | E7: =MIN(0.5/$D7,1) -> 0.25 | F7: =MIN(2/$D7,1) -> 1 | G7: =MIN(8/$D7,1) -> 1 | H7: =MIN(12/$D7,1) -> 1 | I7: =MIN(24/$D7,1) -> 1 | J7: =MIN(72/$D7,1) -> 1
A8: Arkanum | B8: Zirkel | C8: Essenz | D8: 4 | E8: =MIN(0.5/$D8,1) -> 0.125 | F8: =MIN(2/$D8,1) -> 0.5 | G8: =MIN(8/$D8,1) -> 1 | H8: =MIN(12/$D8,1) -> 1 | I8: =MIN(24/$D8,1) -> 1 | J8: =MIN(72/$D8,1) -> 1
A9: Runenwebstuhl | B9: Zwerge | C9: Runen | D9: 8 | E9: =MIN(0.5/$D9,1) -> 0.0625 | F9: =MIN(2/$D9,1) -> 0.25 | G9: =MIN(8/$D9,1) -> 1 | H9: =MIN(12/$D9,1) -> 1 | I9: =MIN(24/$D9,1) -> 1 | J9: =MIN(72/$D9,1) -> 1
A10: Übungshof | B10: Menschen | C10: Helden-XP | D10: 12 | E10: =MIN(0.5/$D10,1) -> 0.041666667 | F10: =MIN(2/$D10,1) -> 0.16666667 | G10: =MIN(8/$D10,1) -> 0.66666667 | H10: =MIN(12/$D10,1) -> 1 | I10: =MIN(24/$D10,1) -> 1 | J10: =MIN(72/$D10,1) -> 1
A11: Skriptorium | B11: Zirkel | C11: Folianten | D11: 24 | E11: =MIN(0.5/$D11,1) -> 0.020833333 | F11: =MIN(2/$D11,1) -> 0.083333333 | G11: =MIN(8/$D11,1) -> 0.33333333 | H11: =MIN(12/$D11,1) -> 0.5 | I11: =MIN(24/$D11,1) -> 1 | J11: =MIN(72/$D11,1) -> 1
A12: Wardenkammer | B12: — | C12: Aufstiegs-Splitter | D12: 48 | E12: =MIN(0.5/$D12,1) -> 0.010416667 | F12: =MIN(2/$D12,1) -> 0.041666667 | G12: =MIN(8/$D12,1) -> 0.16666667 | H12: =MIN(12/$D12,1) -> 0.25 | I12: =MIN(24/$D12,1) -> 0.5 | J12: =MIN(72/$D12,1) -> 1
A14: Volle Gebäude | E14: =COUNTIF(E5:E12,1) -> 1 | F14: =COUNTIF(F5:F12,1) -> 3 | G14: =COUNTIF(G5:G12,1) -> 5 | H14: =COUNTIF(H5:H12,1) -> 6 | I14: =COUNTIF(I5:I12,1) -> 7 | J14: =COUNTIF(J5:J12,1) -> 8
A15: Mindestens eins voll? | E15: =IF(E14>0,"OK","LÜCKE") -> OK | F15: =IF(F14>0,"OK","LÜCKE") -> OK | G15: =IF(G14>0,"OK","LÜCKE") -> OK | H15: =IF(H14>0,"OK","LÜCKE") -> OK | I15: =IF(I14>0,"OK","LÜCKE") -> OK | J15: =IF(J14>0,"OK","LÜCKE") -> OK
